## try-catch-finally
```java
try {

} catch(예외클래스 e) {
    예외처리
} finally {
    항상 실행;
}
```
- try 블록에서 작성한 코드가 예외 없이 정상 실행 되면 catch 블록이 실행되지 않고 finally 블록 실행됨
- try 블록에서 예외가 발생하면 catch 블록이 실행되고 finally 블록 실행됨
- try 블록과 catch 블록에서 return 문을 사용하더라도 finally 블록은 항상 실행됨
- finally 블록은 생략 가능함

### 예시1(예외 처리 전)
```java
public class ExceptionHandlingExample1 {
	public static void printLength(String data) {
		int result = data.length();
		System.out.println("문자 수: " + result);
	}
	
	public static void main(String[] args) {
		System.out.println("[프로그램 시작]\n");
		printLength("ThisIsJava");
		printLength(null);
		System.out.println("[프로그램 종료]");
	}

}
```

### 예시1 결과
```
[프로그램 시작]

문자 수: 10
Exception in thread "main" java.lang.NullPointerException: Cannot invoke "String.length()" because "data" is null
	at ch11.sec02.exam01.ExceptionHandlingExample1.printLength(ExceptionHandlingExample1.java:5)
	at ch11.sec02.exam01.ExceptionHandlingExample1.main(ExceptionHandlingExample1.java:12)
```

### 예시2(예외처리)
```java
public class ExceptionHandlingExample2 {
	public static void printLength(String data) {
	try {
		int result = data.length();
		System.out.println("문자 수: " + result);
		
	} catch(NullPointerException e) {
		System.out.println(e.getMessage());
	} finally {
		System.out.println("[마무리 실행]");
	}
	}
	
	public static void main(String[] args) {
		System.out.println("[프로그램 시작]\n");
		printLength("ThisIsJava");
		printLength(null);
		System.out.println("[프로그램 종료]");
	}

}
```

### 예시2 결과
```
[프로그램 시작]

문자 수: 10
[마무리 실행]
Cannot invoke "String.length()" because "data" is null
[마무리 실행]
[프로그램 종료]
```